<?xml version="1.0" encoding="utf-8"?>
<!-- This URDF was automatically created by SolidWorks to URDF Exporter! Originally created by Stephen Brawner (brawner@gmail.com) 
     Commit Version: 1.6.0-4-g7f85cfe  Build Version: 1.6.7995.38578
     For more information, please see http://wiki.ros.org/sw_urdf_exporter -->
<robot
  name="vehicle_assembly">
  <link
    name="base_link">
    <inertial>
      <origin
        xyz="-0.0224289386788021 1.56831062439276E-05 0.112224892831457"
        rpy="0 0 0" />
      <mass
        value="41.2251605884543" />
      <inertia
        ixx="1.24398926610813"
        ixy="0.000109018410003479"
        ixz="0.132898676032939"
        iyy="2.42715330453507"
        iyz="-0.000164052962245214"
        izz="3.20177683138895" />
    </inertial>
    <visual>
      <origin
        xyz="0 0 0"
        rpy="0 0 0" />
      <geometry>
        <mesh
          filename="package://vehicle_assembly/meshes/base_link.STL" />
      </geometry>
      <material
        name="">
        <color
          rgba="0.792156862745098 0.819607843137255 0.933333333333333 1" />
      </material>
    </visual>
    <collision>
      <origin
        xyz="0 0 0"
        rpy="0 0 0" />
      <geometry>
        <mesh
          filename="package://vehicle_assembly/meshes/base_link.STL" />
      </geometry>
    </collision>
  </link>
  <link
    name="front_right_wheel">
    <inertial>
      <origin
        xyz="9.54791801177635E-15 -9.99200722162641E-16 -0.026867640263798"
        rpy="0 0 0" />
      <mass
        value="0.0386433829117278" />
      <inertia
        ixx="1.34257227551692E-05"
        ixy="4.16154566175428E-21"
        ixz="-2.74623963367605E-22"
        iyy="1.34257227551692E-05"
        iyz="2.06712435077002E-21"
        izz="5.22587319768357E-06" />
    </inertial>
    <visual>
      <origin
        xyz="0 0 0"
        rpy="0 0 0" />
      <geometry>
        <mesh
          filename="package://vehicle_assembly/meshes/front_right_wheel.STL" />
      </geometry>
      <material
        name="">
        <color
          rgba="0.792156862745098 0.819607843137255 0.933333333333333 1" />
      </material>
    </visual>
    <collision>
      <origin
        xyz="0 0 0"
        rpy="0 0 0" />
      <geometry>
        <mesh
          filename="package://vehicle_assembly/meshes/front_right_wheel.STL" />
      </geometry>
    </collision>
  </link>
  <joint
    name="front_right_wheel_joint"
    type="continuous">
    <origin
      xyz="0.296125741132769 -0.29 0.0299999999999979"
      rpy="1.5707963267949 0 0" />
    <parent
      link="base_link" />
    <child
      link="front_right_wheel" />
    <axis
      xyz="0 0 1" />
  </joint>
  <link
    name="front_right_roller_1">
    <inertial>
      <origin
        xyz="0 0 -0.0141999999999921"
        rpy="0 0 0" />
      <mass
        value="0.0026981671245577" />
      <inertia
        ixx="1.63945498983838E-07"
        ixy="-3.30872245021211E-24"
        ixz="-1.29867356170825E-22"
        iyy="1.63945498983838E-07"
        iyz="8.43724224804088E-23"
        izz="4.74186810998576E-08" />
    </inertial>
    <visual>
      <origin
        xyz="0 0 0"
        rpy="0 0 0" />
      <geometry>
        <mesh
          filename="package://vehicle_assembly/meshes/front_right_roller_1.STL" />
      </geometry>
      <material
        name="">
        <color
          rgba="0.792156862745098 0.819607843137255 0.933333333333333 1" />
      </material>
    </visual>
    <collision>
      <origin
        xyz="0 0 0"
        rpy="0 0 0" />
      <geometry>
        <mesh
          filename="package://vehicle_assembly/meshes/front_right_roller_1.STL" />
      </geometry>
    </collision>
  </link>
  <joint
    name="front_right_roller_joint_1"
    type="continuous">
    <origin
      xyz="-0.025136382728163 -0.000933563771401413 -0.00736154021519259"
      rpy="0.766248578899469 -0.193236177895828 -0.182756128842447" />
    <parent
      link="front_right_wheel" />
    <child
      link="front_right_roller_1" />
    <axis
      xyz="0 0 -1" />
  </joint>
  <link
    name="front_right_roller_2">
    <inertial>
      <origin
        xyz="4.44089209850063E-16 -1.11022302462516E-16 -0.014199999999992"
        rpy="0 0 0" />
      <mass
        value="0.00269816712455768" />
      <inertia
        ixx="1.63945498983837E-07"
        ixy="-3.30872245021211E-24"
        ixz="-8.51996030929619E-23"
        iyy="1.63945498983837E-07"
        iyz="-1.65436122510606E-23"
        izz="4.74186810998574E-08" />
    </inertial>
    <visual>
      <origin
        xyz="0 0 0"
        rpy="0 0 0" />
      <geometry>
        <mesh
          filename="package://vehicle_assembly/meshes/front_right_roller_2.STL" />
      </geometry>
      <material
        name="">
        <color
          rgba="0.792156862745098 0.819607843137255 0.933333333333333 1" />
      </material>
    </visual>
    <collision>
      <origin
        xyz="0 0 0"
        rpy="0 0 0" />
      <geometry>
        <mesh
          filename="package://vehicle_assembly/meshes/front_right_roller_2.STL" />
      </geometry>
    </collision>
  </link>
  <joint
    name="front_right_roller_joint_2"
    type="continuous">
    <origin
      xyz="-0.0171139774081526 -0.0184342359550203 -0.00736154021519259"
      rpy="0.785398163397451 0 0.405693456993078" />
    <parent
      link="front_right_wheel" />
    <child
      link="front_right_roller_2" />
    <axis
      xyz="0 0 -1" />
  </joint>
  <link
    name="front_right_roller_3">
    <inertial>
      <origin
        xyz="8.32667268468867E-17 -1.11022302462516E-16 -0.0139999999999922"
        rpy="0 0 0" />
      <mass
        value="0.0026981671245577" />
      <inertia
        ixx="1.63945498983839E-07"
        ixy="-6.61744490042422E-24"
        ixz="-8.8508325543174E-23"
        iyy="1.63945498983839E-07"
        iyz="1.56130340619384E-22"
        izz="4.74186810998577E-08" />
    </inertial>
    <visual>
      <origin
        xyz="0 0 0"
        rpy="0 0 0" />
      <geometry>
        <mesh
          filename="package://vehicle_assembly/meshes/front_right_roller_3.STL" />
      </geometry>
      <material
        name="">
        <color
          rgba="0.792156862745098 0.819607843137255 0.933333333333333 1" />
      </material>
    </visual>
    <collision>
      <origin
        xyz="0 0 0"
        rpy="0 0 0" />
      <geometry>
        <mesh
          filename="package://vehicle_assembly/meshes/front_right_roller_3.STL" />
      </geometry>
    </collision>
  </link>
  <joint
    name="front_right_roller_joint_3"
    type="continuous">
    <origin
      xyz="0.00080221527494384 -0.0250839654364168 -0.00750296157142988"
      rpy="0.785398163397451 0 1.19109162039053" />
    <parent
      link="front_right_wheel" />
    <child
      link="front_right_roller_3" />
    <axis
      xyz="0 0 1" />
  </joint>
  <link
    name="front_right_roller_4">
    <inertial>
      <origin
        xyz="1.11022302462516E-16 0 -0.0139999999999922"
        rpy="0 0 0" />
      <mass
        value="0.00269816712455779" />
      <inertia
        ixx="1.63945498985512E-07"
        ixy="-3.33850095226402E-21"
        ixz="-8.68539643180679E-23"
        iyy="1.63945498985495E-07"
        iyz="-1.78877807464592E-22"
        izz="4.74186811031889E-08" />
    </inertial>
    <visual>
      <origin
        xyz="0 0 0"
        rpy="0 0 0" />
      <geometry>
        <mesh
          filename="package://vehicle_assembly/meshes/front_right_roller_4.STL" />
      </geometry>
      <material
        name="">
        <color
          rgba="0.792156862745098 0.819607843137255 0.933333333333333 1" />
      </material>
    </visual>
    <collision>
      <origin
        xyz="0 0 0"
        rpy="0 0 0" />
      <geometry>
        <mesh
          filename="package://vehicle_assembly/meshes/front_right_roller_4.STL" />
      </geometry>
    </collision>
  </link>
  <joint
    name="front_right_roller_joint_4"
    type="continuous">
    <origin
      xyz="0.0183042939200275 -0.0171697901982628 -0.00750296157142988"
      rpy="0.785398163397451 0 1.97648978378798" />
    <parent
      link="front_right_wheel" />
    <child
      link="front_right_roller_4" />
    <axis
      xyz="0 0 1" />
  </joint>
  <link
    name="front_right_roller_5">
    <inertial>
      <origin
        xyz="2.22044604925031E-16 -2.77555756156289E-17 -0.0139999999999921"
        rpy="0 0 0" />
      <mass
        value="0.00269816712455758" />
      <inertia
        ixx="1.63945498982501E-07"
        ixy="1.65436122510606E-23"
        ixz="-7.52734357423255E-23"
        iyy="1.63945498982501E-07"
        iyz="-4.96308367531817E-23"
        izz="4.741868109739E-08" />
    </inertial>
    <visual>
      <origin
        xyz="0 0 0"
        rpy="0 0 0" />
      <geometry>
        <mesh
          filename="package://vehicle_assembly/meshes/front_right_roller_5.STL" />
      </geometry>
      <material
        name="">
        <color
          rgba="0.792156862745098 0.819607843137255 0.933333333333333 1" />
      </material>
    </visual>
    <collision>
      <origin
        xyz="0 0 0"
        rpy="0 0 0" />
      <geometry>
        <mesh
          filename="package://vehicle_assembly/meshes/front_right_roller_5.STL" />
      </geometry>
    </collision>
  </link>
  <joint
    name="front_right_roller_joint_5"
    type="continuous">
    <origin
      xyz="0.025083965436429 0.000802215274933349 -0.00750296157142988"
      rpy="0.785398163397451 0 2.76188794718543" />
    <parent
      link="front_right_wheel" />
    <child
      link="front_right_roller_5" />
    <axis
      xyz="0 0 1" />
  </joint>
  <link
    name="front_right_roller_6">
    <inertial>
      <origin
        xyz="1.11022302462516E-16 0 -0.0139999999999922"
        rpy="0 0 0" />
      <mass
        value="0.00269816712455759" />
      <inertia
        ixx="1.63945498982287E-07"
        ixy="6.61744490042422E-24"
        ixz="-5.54211010410529E-23"
        iyy="1.63945498982287E-07"
        iyz="-2.31610571514848E-23"
        izz="4.74186810969605E-08" />
    </inertial>
    <visual>
      <origin
        xyz="0 0 0"
        rpy="0 0 0" />
      <geometry>
        <mesh
          filename="package://vehicle_assembly/meshes/front_right_roller_6.STL" />
      </geometry>
      <material
        name="">
        <color
          rgba="0.792156862745098 0.819607843137255 0.933333333333333 1" />
      </material>
    </visual>
    <collision>
      <origin
        xyz="0 0 0"
        rpy="0 0 0" />
      <geometry>
        <mesh
          filename="package://vehicle_assembly/meshes/front_right_roller_6.STL" />
      </geometry>
    </collision>
  </link>
  <joint
    name="front_right_roller_joint_6"
    type="continuous">
    <origin
      xyz="0.017169790198275 0.018304293920017 -0.00750296157142988"
      rpy="0.785398163397451 0 -2.73589919659671" />
    <parent
      link="front_right_wheel" />
    <child
      link="front_right_roller_6" />
    <axis
      xyz="0 0 1" />
  </joint>
  <link
    name="front_right_roller_7">
    <inertial>
      <origin
        xyz="8.32667268468867E-17 -2.22044604925031E-16 -0.013999999999992"
        rpy="0 0 0" />
      <mass
        value="0.00269816712455774" />
      <inertia
        ixx="1.63945498983938E-07"
        ixy="1.65436122510606E-23"
        ixz="-1.57991496997628E-22"
        iyy="1.63945498983938E-07"
        iyz="2.43811485550005E-22"
        izz="4.74186811002666E-08" />
    </inertial>
    <visual>
      <origin
        xyz="0 0 0"
        rpy="0 0 0" />
      <geometry>
        <mesh
          filename="package://vehicle_assembly/meshes/front_right_roller_7.STL" />
      </geometry>
      <material
        name="">
        <color
          rgba="0.792156862745098 0.819607843137255 0.933333333333333 1" />
      </material>
    </visual>
    <collision>
      <origin
        xyz="0 0 0"
        rpy="0 0 0" />
      <geometry>
        <mesh
          filename="package://vehicle_assembly/meshes/front_right_roller_7.STL" />
      </geometry>
    </collision>
  </link>
  <joint
    name="front_right_roller_joint_7"
    type="continuous">
    <origin
      xyz="-0.000802215274921414 0.0250839654364179 -0.00750296157142982"
      rpy="0.785398163397451 0 -1.95050103319926" />
    <parent
      link="front_right_wheel" />
    <child
      link="front_right_roller_7" />
    <axis
      xyz="0 0 1" />
  </joint>
  <link
    name="front_right_roller_8">
    <inertial>
      <origin
        xyz="-1.11022302462516E-16 -1.11022302462516E-16 -0.0139999999999922"
        rpy="0 0 0" />
      <mass
        value="0.00269816712455774" />
      <inertia
        ixx="1.63945498985208E-07"
        ixy="1.32348898008484E-23"
        ixz="-2.81241408268029E-23"
        iyy="1.63945498985208E-07"
        iyz="-3.20532487364298E-23"
        izz="4.74186811023884E-08" />
    </inertial>
    <visual>
      <origin
        xyz="0 0 0"
        rpy="0 0 0" />
      <geometry>
        <mesh
          filename="package://vehicle_assembly/meshes/front_right_roller_8.STL" />
      </geometry>
      <material
        name="">
        <color
          rgba="0.792156862745098 0.819607843137255 0.933333333333333 1" />
      </material>
    </visual>
    <collision>
      <origin
        xyz="0 0 0"
        rpy="0 0 0" />
      <geometry>
        <mesh
          filename="package://vehicle_assembly/meshes/front_right_roller_8.STL" />
      </geometry>
    </collision>
  </link>
  <joint
    name="front_right_roller_joint_8"
    type="continuous">
    <origin
      xyz="-0.0183042939200047 0.0171697901982646 -0.00750296157142988"
      rpy="0.785398163397451 0 -1.16510286980182" />
    <parent
      link="front_right_wheel" />
    <child
      link="front_right_roller_8" />
    <axis
      xyz="0 0 1" />
  </joint>
  <link
    name="rear_right_wheel">
    <inertial>
      <origin
        xyz="-4.44089209850063E-16 -3.33066907387547E-16 -0.0268676402673231"
        rpy="0 0 0" />
      <mass
        value="0.038643382868784" />
      <inertia
        ixx="1.34257227518845E-05"
        ixy="-3.61147055440652E-21"
        ixz="2.00839452727875E-21"
        iyy="1.34257227518845E-05"
        iyz="-6.5843576759221E-22"
        izz="5.22587319547653E-06" />
    </inertial>
    <visual>
      <origin
        xyz="0 0 0"
        rpy="0 0 0" />
      <geometry>
        <mesh
          filename="package://vehicle_assembly/meshes/rear_right_wheel.STL" />
      </geometry>
      <material
        name="">
        <color
          rgba="0.792156862745098 0.819607843137255 0.933333333333333 1" />
      </material>
    </visual>
    <collision>
      <origin
        xyz="0 0 0"
        rpy="0 0 0" />
      <geometry>
        <mesh
          filename="package://vehicle_assembly/meshes/rear_right_wheel.STL" />
      </geometry>
    </collision>
  </link>
  <joint
    name="rear_right_wheel_joint"
    type="continuous">
    <origin
      xyz="-0.287691876046496 -0.29 0.0300000000000009"
      rpy="1.5707963267949 0 0" />
    <parent
      link="base_link" />
    <child
      link="rear_right_wheel" />
    <axis
      xyz="0 0 1" />
  </joint>
  <link
    name="rear_right_roller_1">
    <inertial>
      <origin
        xyz="2.22044604925031E-16 -1.11022302462516E-16 -0.0139999999999923"
        rpy="0 0 0" />
      <mass
        value="0.00269816712455773" />
      <inertia
        ixx="1.63945498985603E-07"
        ixy="3.30872245021211E-24"
        ixz="-4.4254162771587E-23"
        iyy="1.63945498985602E-07"
        iyz="-4.96308367531817E-24"
        izz="4.74186811031799E-08" />
    </inertial>
    <visual>
      <origin
        xyz="0 0 0"
        rpy="0 0 0" />
      <geometry>
        <mesh
          filename="package://vehicle_assembly/meshes/rear_right_roller_1.STL" />
      </geometry>
      <material
        name="">
        <color
          rgba="0.792156862745098 0.819607843137255 0.933333333333333 1" />
      </material>
    </visual>
    <collision>
      <origin
        xyz="0 0 0"
        rpy="0 0 0" />
      <geometry>
        <mesh
          filename="package://vehicle_assembly/meshes/rear_right_roller_1.STL" />
      </geometry>
    </collision>
  </link>
  <joint
    name="rear_right_roller_joint_1"
    type="continuous">
    <origin
      xyz="0.00546345688911121 0.0244948874294918 -0.00750296157142988"
      rpy="-0.623153977285637 -0.514017351689894 0.33966567667138" />
    <parent
      link="rear_right_wheel" />
    <child
      link="rear_right_roller_1" />
    <axis
      xyz="0 0 1" />
  </joint>
  <link
    name="rear_right_roller_2">
    <inertial>
      <origin
        xyz="-1.11022302462516E-16 0 -0.0139999999999921"
        rpy="0 0 0" />
      <mass
        value="0.00269816712455764" />
      <inertia
        ixx="1.63945498982508E-07"
        ixy="0"
        ixz="1.3524403015242E-22"
        iyy="1.63945498982508E-07"
        iyz="2.15066959263787E-23"
        izz="4.74186810974015E-08" />
    </inertial>
    <visual>
      <origin
        xyz="0 0 0"
        rpy="0 0 0" />
      <geometry>
        <mesh
          filename="package://vehicle_assembly/meshes/rear_right_roller_2.STL" />
      </geometry>
      <material
        name="">
        <color
          rgba="0.792156862745098 0.819607843137255 0.933333333333333 1" />
      </material>
    </visual>
    <collision>
      <origin
        xyz="0 0 0"
        rpy="0 0 0" />
      <geometry>
        <mesh
          filename="package://vehicle_assembly/meshes/rear_right_roller_2.STL" />
      </geometry>
    </collision>
  </link>
  <joint
    name="rear_right_roller_joint_2"
    type="continuous">
    <origin
      xyz="-0.0134572535907849 0.0211837484208044 -0.00750296157142988"
      rpy="0.211571775494453 -0.762323422646798 -0.147258376597581" />
    <parent
      link="rear_right_wheel" />
    <child
      link="rear_right_roller_2" />
    <axis
      xyz="0 0 -1" />
  </joint>
  <link
    name="rear_right_roller_3">
    <inertial>
      <origin
        xyz="1.11022302462516E-16 0 -0.0139999999999922"
        rpy="0 0 0" />
      <mass
        value="0.00269816712455764" />
      <inertia
        ixx="1.63945498983626E-07"
        ixy="3.30872245021211E-24"
        ixz="-1.48892510259545E-23"
        iyy="1.63945498983626E-07"
        iyz="5.29395592033938E-23"
        izz="4.74186810994344E-08" />
    </inertial>
    <visual>
      <origin
        xyz="0 0 0"
        rpy="0 0 0" />
      <geometry>
        <mesh
          filename="package://vehicle_assembly/meshes/rear_right_roller_3.STL" />
      </geometry>
      <material
        name="">
        <color
          rgba="0.792156862745098 0.819607843137255 0.933333333333333 1" />
      </material>
    </visual>
    <collision>
      <origin
        xyz="0 0 0"
        rpy="0 0 0" />
      <geometry>
        <mesh
          filename="package://vehicle_assembly/meshes/rear_right_roller_3.STL" />
      </geometry>
    </collision>
  </link>
  <joint
    name="rear_right_roller_joint_3"
    type="continuous">
    <origin
      xyz="-0.0244948874294926 0.0054634568891084 -0.00750296157142988"
      rpy="0.785398163397451 0 -0.631127670755188" />
    <parent
      link="rear_right_wheel" />
    <child
      link="rear_right_roller_3" />
    <axis
      xyz="0 0 -1" />
  </joint>
  <link
    name="rear_right_roller_4">
    <inertial>
      <origin
        xyz="-5.55111512312578E-17 0 -0.0139999999999922"
        rpy="0 0 0" />
      <mass
        value="0.00269816712455769" />
      <inertia
        ixx="1.63945498985194E-07"
        ixy="6.61744490042422E-24"
        ixz="2.19202862326552E-23"
        iyy="1.63945498985194E-07"
        iyz="3.14328632770151E-23"
        izz="4.74186811023605E-08" />
    </inertial>
    <visual>
      <origin
        xyz="0 0 0"
        rpy="0 0 0" />
      <geometry>
        <mesh
          filename="package://vehicle_assembly/meshes/rear_right_roller_4.STL" />
      </geometry>
      <material
        name="">
        <color
          rgba="0.792156862745098 0.819607843137255 0.933333333333333 1" />
      </material>
    </visual>
    <collision>
      <origin
        xyz="0 0 0"
        rpy="0 0 0" />
      <geometry>
        <mesh
          filename="package://vehicle_assembly/meshes/rear_right_roller_4.STL" />
      </geometry>
    </collision>
  </link>
  <joint
    name="rear_right_roller_joint_4"
    type="continuous">
    <origin
      xyz="-0.0211837484208052 -0.0134572535907877 -0.00750296157142988"
      rpy="0.785398163397451 0 0.154270492642262" />
    <parent
      link="rear_right_wheel" />
    <child
      link="rear_right_roller_4" />
    <axis
      xyz="0 0 -1" />
  </joint>
  <link
    name="rear_right_roller_5">
    <inertial>
      <origin
        xyz="0 -2.77555756156289E-17 -0.013999999999992"
        rpy="0 0 0" />
      <mass
        value="0.00269816712455765" />
      <inertia
        ixx="1.63945498982565E-07"
        ixy="1.65436122510606E-23"
        ixz="-4.13590306276514E-23"
        iyy="1.63945498982565E-07"
        iyz="1.19941188820189E-22"
        izz="4.74186810973101E-08" />
    </inertial>
    <visual>
      <origin
        xyz="0 0 0"
        rpy="0 0 0" />
      <geometry>
        <mesh
          filename="package://vehicle_assembly/meshes/rear_right_roller_5.STL" />
      </geometry>
      <material
        name="">
        <color
          rgba="0.792156862745098 0.819607843137255 0.933333333333333 1" />
      </material>
    </visual>
    <collision>
      <origin
        xyz="0 0 0"
        rpy="0 0 0" />
      <geometry>
        <mesh
          filename="package://vehicle_assembly/meshes/rear_right_roller_5.STL" />
      </geometry>
    </collision>
  </link>
  <joint
    name="rear_right_roller_joint_5"
    type="continuous">
    <origin
      xyz="-0.0054634568891091 -0.0244948874294954 -0.00750296157142988"
      rpy="0.785398163397451 0 0.939668656039712" />
    <parent
      link="rear_right_wheel" />
    <child
      link="rear_right_roller_5" />
    <axis
      xyz="0 0 -1" />
  </joint>
  <link
    name="rear_right_roller_6">
    <inertial>
      <origin
        xyz="-1.11022302462516E-16 2.77555756156289E-17 -0.013999999999992"
        rpy="0 0 0" />
      <mass
        value="0.00269816712455759" />
      <inertia
        ixx="1.63945498982502E-07"
        ixy="-3.30872245021211E-24"
        ixz="6.16249556352006E-23"
        iyy="1.63945498982502E-07"
        iyz="1.07688575996747E-22"
        izz="4.74186810973902E-08" />
    </inertial>
    <visual>
      <origin
        xyz="0 0 0"
        rpy="0 0 0" />
      <geometry>
        <mesh
          filename="package://vehicle_assembly/meshes/rear_right_roller_6.STL" />
      </geometry>
      <material
        name="">
        <color
          rgba="0.792156862745098 0.819607843137255 0.933333333333333 1" />
      </material>
    </visual>
    <collision>
      <origin
        xyz="0 0 0"
        rpy="0 0 0" />
      <geometry>
        <mesh
          filename="package://vehicle_assembly/meshes/rear_right_roller_6.STL" />
      </geometry>
    </collision>
  </link>
  <joint
    name="rear_right_roller_joint_6"
    type="continuous">
    <origin
      xyz="0.0134572535907871 -0.0211837484208079 -0.00750296157142988"
      rpy="0.785398163397451 0 1.72506681943716" />
    <parent
      link="rear_right_wheel" />
    <child
      link="rear_right_roller_6" />
    <axis
      xyz="0 0 -1" />
  </joint>
  <link
    name="rear_right_roller_7">
    <inertial>
      <origin
        xyz="0 -2.77555756156289E-17 -0.0141999999999923"
        rpy="0 0 0" />
      <mass
        value="0.00269816712455769" />
      <inertia
        ixx="1.63945498984811E-07"
        ixy="-1.32348898008484E-23"
        ixz="-6.28657265540301E-23"
        iyy="1.63945498984811E-07"
        iyz="-2.31610571514848E-23"
        izz="4.74186811015957E-08" />
    </inertial>
    <visual>
      <origin
        xyz="0 0 0"
        rpy="0 0 0" />
      <geometry>
        <mesh
          filename="package://vehicle_assembly/meshes/rear_right_roller_7.STL" />
      </geometry>
      <material
        name="">
        <color
          rgba="0.792156862745098 0.819607843137255 0.933333333333333 1" />
      </material>
    </visual>
    <collision>
      <origin
        xyz="0 0 0"
        rpy="0 0 0" />
      <geometry>
        <mesh
          filename="package://vehicle_assembly/meshes/rear_right_roller_7.STL" />
      </geometry>
    </collision>
  </link>
  <joint
    name="rear_right_roller_joint_7"
    type="continuous">
    <origin
      xyz="0.0245783338887628 -0.00534927857052381 -0.00736154021519253"
      rpy="0.785398163397451 0 2.51046498283461" />
    <parent
      link="rear_right_wheel" />
    <child
      link="rear_right_roller_7" />
    <axis
      xyz="0 0 -1" />
  </joint>
  <link
    name="rear_right_roller_8">
    <inertial>
      <origin
        xyz="1.11022302462516E-16 -5.55111512312578E-17 -0.0139999999999922"
        rpy="0 0 0" />
      <mass
        value="0.00269816712455769" />
      <inertia
        ixx="1.63945498983915E-07"
        ixy="-4.96308367531817E-24"
        ixz="-3.35008148083976E-23"
        iyy="1.63945498983915E-07"
        iyz="4.30133918527574E-23"
        izz="4.74186811002196E-08" />
    </inertial>
    <visual>
      <origin
        xyz="0 0 0"
        rpy="0 0 0" />
      <geometry>
        <mesh
          filename="package://vehicle_assembly/meshes/rear_right_roller_8.STL" />
      </geometry>
      <material
        name="">
        <color
          rgba="0.792156862745098 0.819607843137255 0.933333333333333 1" />
      </material>
    </visual>
    <collision>
      <origin
        xyz="0 0 0"
        rpy="0 0 0" />
      <geometry>
        <mesh
          filename="package://vehicle_assembly/meshes/rear_right_roller_8.STL" />
      </geometry>
    </collision>
  </link>
  <joint
    name="rear_right_roller_joint_8"
    type="continuous">
    <origin
      xyz="0.0211837484208072 0.013457253590784 -0.00750296157142988"
      rpy="0.785398163397451 0 -2.98732216094754" />
    <parent
      link="rear_right_wheel" />
    <child
      link="rear_right_roller_8" />
    <axis
      xyz="0 0 -1" />
  </joint>
  <link
    name="rear_left_wheel">
    <inertial>
      <origin
        xyz="2.22044604925031E-16 0 -0.0268676402646212"
        rpy="0 0 0" />
      <mass
        value="0.0386433828852301" />
      <inertia
        ixx="1.34257227530065E-05"
        ixy="3.31699425633764E-21"
        ixz="1.08360660244447E-21"
        iyy="1.34257227530065E-05"
        iyz="8.78465810531315E-22"
        izz="5.22587319926349E-06" />
    </inertial>
    <visual>
      <origin
        xyz="0 0 0"
        rpy="0 0 0" />
      <geometry>
        <mesh
          filename="package://vehicle_assembly/meshes/rear_left_wheel.STL" />
      </geometry>
      <material
        name="">
        <color
          rgba="0.792156862745098 0.819607843137255 0.933333333333333 1" />
      </material>
    </visual>
    <collision>
      <origin
        xyz="0 0 0"
        rpy="0 0 0" />
      <geometry>
        <mesh
          filename="package://vehicle_assembly/meshes/rear_left_wheel.STL" />
      </geometry>
    </collision>
  </link>
  <joint
    name="rear_left_wheel_joint"
    type="continuous">
    <origin
      xyz="-0.287691876046497 0.29 0.0300000000000001"
      rpy="-1.5707963267949 0 0" />
    <parent
      link="base_link" />
    <child
      link="rear_left_wheel" />
    <axis
      xyz="0 0 1" />
  </joint>
  <link
    name="rear_left_roller_1">
    <inertial>
      <origin
        xyz="5.55111512312578E-17 -5.55111512312578E-17 -0.0139999999999922"
        rpy="0 0 0" />
      <mass
        value="0.00269816712455764" />
      <inertia
        ixx="1.63945498982479E-07"
        ixy="-6.61744490042422E-24"
        ixz="4.13590306276514E-25"
        iyy="1.63945498982479E-07"
        iyz="3.63959469523332E-23"
        izz="4.74186810973482E-08" />
    </inertial>
    <visual>
      <origin
        xyz="0 0 0"
        rpy="0 0 0" />
      <geometry>
        <mesh
          filename="package://vehicle_assembly/meshes/rear_left_roller_1.STL" />
      </geometry>
      <material
        name="">
        <color
          rgba="0.792156862745098 0.819607843137255 0.933333333333333 1" />
      </material>
    </visual>
    <collision>
      <origin
        xyz="0 0 0"
        rpy="0 0 0" />
      <geometry>
        <mesh
          filename="package://vehicle_assembly/meshes/rear_left_roller_1.STL" />
      </geometry>
    </collision>
  </link>
  <joint
    name="rear_left_roller_joint_1"
    type="continuous">
    <origin
      xyz="-0.012643793705906 -0.0216790994297534 -0.00750296157142993"
      rpy="0.726359838780016 0.330625265585473 0.280780785805676" />
    <parent
      link="rear_left_wheel" />
    <child
      link="rear_left_roller_1" />
    <axis
      xyz="0 0 1" />
  </joint>
  <link
    name="rear_left_roller_2">
    <inertial>
      <origin
        xyz="-5.55111512312578E-17 0 -0.0139999999999922"
        rpy="0 0 0" />
      <mass
        value="0.00269816712455759" />
      <inertia
        ixx="1.63945498982287E-07"
        ixy="-2.48154183765908E-24"
        ixz="5.8729823491265E-23"
        iyy="1.63945498982287E-07"
        iyz="7.77549775799846E-23"
        izz="4.74186810969594E-08" />
    </inertial>
    <visual>
      <origin
        xyz="0 0 0"
        rpy="0 0 0" />
      <geometry>
        <mesh
          filename="package://vehicle_assembly/meshes/rear_left_roller_2.STL" />
      </geometry>
      <material
        name="">
        <color
          rgba="0.792156862745098 0.819607843137255 0.933333333333333 1" />
      </material>
    </visual>
    <collision>
      <origin
        xyz="0 0 0"
        rpy="0 0 0" />
      <geometry>
        <mesh
          filename="package://vehicle_assembly/meshes/rear_left_roller_2.STL" />
      </geometry>
    </collision>
  </link>
  <joint
    name="rear_left_roller_joint_2"
    type="continuous">
    <origin
      xyz="-0.0242699504861661 -0.0063889259474246 -0.00750296157142993"
      rpy="0.782393541200266 -0.0773643643473035 -0.0766735609008714" />
    <parent
      link="rear_left_wheel" />
    <child
      link="rear_left_roller_2" />
    <axis
      xyz="0 0 1" />
  </joint>
  <link
    name="rear_left_roller_3">
    <inertial>
      <origin
        xyz="-5.55111512312578E-17 0 -0.0139999999999922"
        rpy="0 0 0" />
      <mass
        value="0.00269816712455775" />
      <inertia
        ixx="1.63945498984686E-07"
        ixy="-1.32348898008484E-23"
        ixz="2.8951321439356E-23"
        iyy="1.63945498984686E-07"
        iyz="7.11375326795604E-23"
        izz="4.74186811015538E-08" />
    </inertial>
    <visual>
      <origin
        xyz="0 0 0"
        rpy="0 0 0" />
      <geometry>
        <mesh
          filename="package://vehicle_assembly/meshes/rear_left_roller_3.STL" />
      </geometry>
      <material
        name="">
        <color
          rgba="0.792156862745098 0.819607843137255 0.933333333333333 1" />
      </material>
    </visual>
    <collision>
      <origin
        xyz="0 0 0"
        rpy="0 0 0" />
      <geometry>
        <mesh
          filename="package://vehicle_assembly/meshes/rear_left_roller_3.STL" />
      </geometry>
    </collision>
  </link>
  <joint
    name="rear_left_roller_joint_3"
    type="continuous">
    <origin
      xyz="-0.0216790994297526 0.0126437937059088 -0.00750296157142993"
      rpy="0.623153977285602 -0.514017351689939 -0.339665676671382" />
    <parent
      link="rear_left_wheel" />
    <child
      link="rear_left_roller_3" />
    <axis
      xyz="0 0 1" />
  </joint>
  <link
    name="rear_left_roller_4">
    <inertial>
      <origin
        xyz="-1.11022302462516E-16 -8.32667268468867E-17 -0.0139999999999922"
        rpy="0 0 0" />
      <mass
        value="0.00269816712455779" />
      <inertia
        ixx="1.63945498985522E-07"
        ixy="-6.61744490042422E-24"
        ixz="-5.04580173657347E-23"
        iyy="1.63945498985522E-07"
        iyz="-1.65022532204329E-22"
        izz="4.74186811032269E-08" />
    </inertial>
    <visual>
      <origin
        xyz="0 0 0"
        rpy="0 0 0" />
      <geometry>
        <mesh
          filename="package://vehicle_assembly/meshes/rear_left_roller_4.STL" />
      </geometry>
      <material
        name="">
        <color
          rgba="0.792156862745098 0.819607843137255 0.933333333333333 1" />
      </material>
    </visual>
    <collision>
      <origin
        xyz="0 0 0"
        rpy="0 0 0" />
      <geometry>
        <mesh
          filename="package://vehicle_assembly/meshes/rear_left_roller_4.STL" />
      </geometry>
    </collision>
  </link>
  <joint
    name="rear_left_roller_joint_4"
    type="continuous">
    <origin
      xyz="-0.0063889259474238 0.0242699504861689 -0.00750296157142993"
      rpy="-0.211571775494547 -0.762323422646777 0.147258376597644" />
    <parent
      link="rear_left_wheel" />
    <child
      link="rear_left_roller_4" />
    <axis
      xyz="0 0 1" />
  </joint>
  <link
    name="rear_left_roller_5">
    <inertial>
      <origin
        xyz="-1.11022302462516E-16 5.55111512312578E-17 -0.0139999999999922"
        rpy="0 0 0" />
      <mass
        value="0.00269816712455759" />
      <inertia
        ixx="1.63945498982482E-07"
        ixy="3.30872245021211E-24"
        ixz="-6.28657265540301E-23"
        iyy="1.63945498982482E-07"
        iyz="1.32348898008484E-23"
        izz="4.74186810973545E-08" />
    </inertial>
    <visual>
      <origin
        xyz="0 0 0"
        rpy="0 0 0" />
      <geometry>
        <mesh
          filename="package://vehicle_assembly/meshes/rear_left_roller_5.STL" />
      </geometry>
      <material
        name="">
        <color
          rgba="0.792156862745098 0.819607843137255 0.933333333333333 1" />
      </material>
    </visual>
    <collision>
      <origin
        xyz="0 0 0"
        rpy="0 0 0" />
      <geometry>
        <mesh
          filename="package://vehicle_assembly/meshes/rear_left_roller_5.STL" />
      </geometry>
    </collision>
  </link>
  <joint
    name="rear_left_roller_joint_5"
    type="continuous">
    <origin
      xyz="0.0126437937059088 0.021679099429755 -0.00750296157142988"
      rpy="-0.726359838780014 -0.330625265585477 0.280780785805678" />
    <parent
      link="rear_left_wheel" />
    <child
      link="rear_left_roller_5" />
    <axis
      xyz="0 0 1" />
  </joint>
  <link
    name="rear_left_roller_6">
    <inertial>
      <origin
        xyz="1.11022302462516E-16 0 -0.0139999999999922"
        rpy="0 0 0" />
      <mass
        value="0.00269816712455774" />
      <inertia
        ixx="1.63945498985603E-07"
        ixy="8.27180612553028E-25"
        ixz="-2.37814426108995E-23"
        iyy="1.63945498985603E-07"
        iyz="-2.9778502051909E-23"
        izz="4.74186811031801E-08" />
    </inertial>
    <visual>
      <origin
        xyz="0 0 0"
        rpy="0 0 0" />
      <geometry>
        <mesh
          filename="package://vehicle_assembly/meshes/rear_left_roller_6.STL" />
      </geometry>
      <material
        name="">
        <color
          rgba="0.792156862745098 0.819607843137255 0.933333333333333 1" />
      </material>
    </visual>
    <collision>
      <origin
        xyz="0 0 0"
        rpy="0 0 0" />
      <geometry>
        <mesh
          filename="package://vehicle_assembly/meshes/rear_left_roller_6.STL" />
      </geometry>
    </collision>
  </link>
  <joint
    name="rear_left_roller_joint_6"
    type="continuous">
    <origin
      xyz="0.0242699504861695 0.00638892594742668 -0.00750296157142993"
      rpy="-0.782393541200267 0.0773643643473 -0.0766735609008679" />
    <parent
      link="rear_left_wheel" />
    <child
      link="rear_left_roller_6" />
    <axis
      xyz="0 0 1" />
  </joint>
  <link
    name="rear_left_roller_7">
    <inertial>
      <origin
        xyz="2.77555756156289E-17 -2.77555756156289E-17 -0.0139999999999922"
        rpy="0 0 0" />
      <mass
        value="0.00269816712455764" />
      <inertia
        ixx="1.63945498983627E-07"
        ixy="1.98523347012727E-23"
        ixz="9.59529510561512E-23"
        iyy="1.63945498983627E-07"
        iyz="1.48892510259545E-23"
        izz="4.74186810994343E-08" />
    </inertial>
    <visual>
      <origin
        xyz="0 0 0"
        rpy="0 0 0" />
      <geometry>
        <mesh
          filename="package://vehicle_assembly/meshes/rear_left_roller_7.STL" />
      </geometry>
      <material
        name="">
        <color
          rgba="0.792156862745098 0.819607843137255 0.933333333333333 1" />
      </material>
    </visual>
    <collision>
      <origin
        xyz="0 0 0"
        rpy="0 0 0" />
      <geometry>
        <mesh
          filename="package://vehicle_assembly/meshes/rear_left_roller_7.STL" />
      </geometry>
    </collision>
  </link>
  <joint
    name="rear_left_roller_joint_7"
    type="continuous">
    <origin
      xyz="0.0216790994297561 -0.0126437937059067 -0.00750296157142993"
      rpy="-0.785398163397451 0 -0.93966865603977" />
    <parent
      link="rear_left_wheel" />
    <child
      link="rear_left_roller_7" />
    <axis
      xyz="0 0 1" />
  </joint>
  <link
    name="rear_left_roller_8">
    <inertial>
      <origin
        xyz="5.55111512312578E-17 5.55111512312578E-17 -0.0139999999999921"
        rpy="0 0 0" />
      <mass
        value="0.00269816712455759" />
      <inertia
        ixx="1.63945498982285E-07"
        ixy="6.61744490042422E-24"
        ixz="-3.22600438895681E-23"
        iyy="1.63945498982285E-07"
        iyz="1.83013710527357E-23"
        izz="4.74186810969594E-08" />
    </inertial>
    <visual>
      <origin
        xyz="0 0 0"
        rpy="0 0 0" />
      <geometry>
        <mesh
          filename="package://vehicle_assembly/meshes/rear_left_roller_8.STL" />
      </geometry>
      <material
        name="">
        <color
          rgba="0.792156862745098 0.819607843137255 0.933333333333333 1" />
      </material>
    </visual>
    <collision>
      <origin
        xyz="0 0 0"
        rpy="0 0 0" />
      <geometry>
        <mesh
          filename="package://vehicle_assembly/meshes/rear_left_roller_8.STL" />
      </geometry>
    </collision>
  </link>
  <joint
    name="rear_left_roller_joint_8"
    type="continuous">
    <origin
      xyz="0.00638892594742735 -0.0242699504861669 -0.00750296157142993"
      rpy="-0.785398163397451 0 -1.72506681943722" />
    <parent
      link="rear_left_wheel" />
    <child
      link="rear_left_roller_8" />
    <axis
      xyz="0 0 1" />
  </joint>
  <link
    name="front_left_wheel">
    <inertial>
      <origin
        xyz="1.08801856413265E-14 1.13797860024079E-15 -0.0268676402638755"
        rpy="0 0 0" />
      <mass
        value="0.0386433829109976" />
      <inertia
        ixx="1.3425722755107E-05"
        ixy="-3.891884782062E-21"
        ixz="3.30872245021211E-22"
        iyy="1.3425722755107E-05"
        iyz="2.98777637254154E-21"
        izz="5.22587319747601E-06" />
    </inertial>
    <visual>
      <origin
        xyz="0 0 0"
        rpy="0 0 0" />
      <geometry>
        <mesh
          filename="package://vehicle_assembly/meshes/front_left_wheel.STL" />
      </geometry>
      <material
        name="">
        <color
          rgba="0.792156862745098 0.819607843137255 0.933333333333333 1" />
      </material>
    </visual>
    <collision>
      <origin
        xyz="0 0 0"
        rpy="0 0 0" />
      <geometry>
        <mesh
          filename="package://vehicle_assembly/meshes/front_left_wheel.STL" />
      </geometry>
    </collision>
  </link>
  <joint
    name="front_left_wheel_joint"
    type="continuous">
    <origin
      xyz="0.29612574113277 0.29 0.0300000000000017"
      rpy="-1.5707963267949 0 0" />
    <parent
      link="base_link" />
    <child
      link="front_left_wheel" />
    <axis
      xyz="0 0 1" />
  </joint>
  <link
    name="front_left_roller_1">
    <inertial>
      <origin
        xyz="-4.44089209850063E-16 0 -0.0139999999999922"
        rpy="0 0 0" />
      <mass
        value="0.0026981671245577" />
      <inertia
        ixx="1.63945498983613E-07"
        ixy="1.65436122510606E-24"
        ixz="-8.10637000301967E-23"
        iyy="1.63945498983613E-07"
        iyz="-7.44462551297725E-23"
        izz="4.7418681099409E-08" />
    </inertial>
    <visual>
      <origin
        xyz="0 0 0"
        rpy="0 0 0" />
      <geometry>
        <mesh
          filename="package://vehicle_assembly/meshes/front_left_roller_1.STL" />
      </geometry>
      <material
        name="">
        <color
          rgba="0.792156862745098 0.819607843137255 0.933333333333333 1" />
      </material>
    </visual>
    <collision>
      <origin
        xyz="0 0 0"
        rpy="0 0 0" />
      <geometry>
        <mesh
          filename="package://vehicle_assembly/meshes/front_left_roller_1.STL" />
      </geometry>
    </collision>
  </link>
  <joint
    name="front_left_roller_joint_1"
    type="continuous">
    <origin
      xyz="0.0250963410938483 0.000150116835983372 -0.00750296157142988"
      rpy="-0.763346740733763 0.206966081028483 -0.194146383614585" />
    <parent
      link="front_left_wheel" />
    <child
      link="front_left_roller_1" />
    <axis
      xyz="0 0 1" />
  </joint>
  <link
    name="front_left_roller_2">
    <inertial>
      <origin
        xyz="1.11022302462516E-16 -1.38777878078145E-17 -0.0139999999999921"
        rpy="0 0 0" />
      <mass
        value="0.00269816712455758" />
      <inertia
        ixx="1.63945498982483E-07"
        ixy="9.92616735063633E-24"
        ixz="-2.13412598038681E-22"
        iyy="1.63945498982483E-07"
        iyz="-2.15066959263787E-23"
        izz="4.74186810973545E-08" />
    </inertial>
    <visual>
      <origin
        xyz="0 0 0"
        rpy="0 0 0" />
      <geometry>
        <mesh
          filename="package://vehicle_assembly/meshes/front_left_roller_2.STL" />
      </geometry>
      <material
        name="">
        <color
          rgba="0.792156862745098 0.819607843137255 0.933333333333333 1" />
      </material>
    </visual>
    <collision>
      <origin
        xyz="0 0 0"
        rpy="0 0 0" />
      <geometry>
        <mesh
          filename="package://vehicle_assembly/meshes/front_left_roller_2.STL" />
      </geometry>
    </collision>
  </link>
  <joint
    name="front_left_roller_joint_2"
    type="continuous">
    <origin
      xyz="0.0178519416031255 -0.0176396443377288 -0.00750296157142988"
      rpy="-0.456823171945388 0.663406127651244 -0.293901499682203" />
    <parent
      link="front_left_wheel" />
    <child
      link="front_left_roller_2" />
    <axis
      xyz="0 0 1" />
  </joint>
  <link
    name="front_left_roller_3">
    <inertial>
      <origin
        xyz="-1.11022302462516E-16 0 -0.0139999999999922"
        rpy="0 0 0" />
      <mass
        value="0.00269816712455774" />
      <inertia
        ixx="1.63945498983862E-07"
        ixy="0"
        ixz="7.50666405891873E-23"
        iyy="1.63945498983862E-07"
        iyz="8.27180612553028E-24"
        izz="4.74186810999045E-08" />
    </inertial>
    <visual>
      <origin
        xyz="0 0 0"
        rpy="0 0 0" />
      <geometry>
        <mesh
          filename="package://vehicle_assembly/meshes/front_left_roller_3.STL" />
      </geometry>
      <material
        name="">
        <color
          rgba="0.792156862745098 0.819607843137255 0.933333333333333 1" />
      </material>
    </visual>
    <collision>
      <origin
        xyz="0 0 0"
        rpy="0 0 0" />
      <geometry>
        <mesh
          filename="package://vehicle_assembly/meshes/front_left_roller_3.STL" />
      </geometry>
    </collision>
  </link>
  <joint
    name="front_left_roller_joint_3"
    type="continuous">
    <origin
      xyz="0.000150116835990088 -0.0250963410938354 -0.00750296157142988"
      rpy="0.478857784316732 0.64894724705125 0.30402620999101" />
    <parent
      link="front_left_wheel" />
    <child
      link="front_left_roller_3" />
    <axis
      xyz="0 0 1" />
  </joint>
  <link
    name="front_left_roller_4">
    <inertial>
      <origin
        xyz="0 -1.11022302462516E-16 -0.0139999999999922"
        rpy="0 0 0" />
      <mass
        value="0.00269816712455769" />
      <inertia
        ixx="1.63945498983614E-07"
        ixy="-6.61744490042422E-24"
        ixz="-1.8859717966209E-22"
        iyy="1.63945498983614E-07"
        iyz="4.30133918527574E-23"
        izz="4.7418681099409E-08" />
    </inertial>
    <visual>
      <origin
        xyz="0 0 0"
        rpy="0 0 0" />
      <geometry>
        <mesh
          filename="package://vehicle_assembly/meshes/front_left_roller_4.STL" />
      </geometry>
      <material
        name="">
        <color
          rgba="0.792156862745098 0.819607843137255 0.933333333333333 1" />
      </material>
    </visual>
    <collision>
      <origin
        xyz="0 0 0"
        rpy="0 0 0" />
      <geometry>
        <mesh
          filename="package://vehicle_assembly/meshes/front_left_roller_4.STL" />
      </geometry>
    </collision>
  </link>
  <joint
    name="front_left_roller_joint_4"
    type="continuous">
    <origin
      xyz="-0.017639644337722 -0.0178519416031125 -0.00750296157142988"
      rpy="0.766248578899477 0.19323617789579 0.182756128842415" />
    <parent
      link="front_left_wheel" />
    <child
      link="front_left_roller_4" />
    <axis
      xyz="0 0 1" />
  </joint>
  <link
    name="front_left_roller_5">
    <inertial>
      <origin
        xyz="-2.22044604925031E-16 5.55111512312578E-17 -0.0139999999999922"
        rpy="0 0 0" />
      <mass
        value="0.00269816712455775" />
      <inertia
        ixx="1.63945498985329E-07"
        ixy="0"
        ixz="8.14772903364732E-23"
        iyy="1.63945498985329E-07"
        iyz="2.31610571514848E-23"
        izz="4.74186811028383E-08" />
    </inertial>
    <visual>
      <origin
        xyz="0 0 0"
        rpy="0 0 0" />
      <geometry>
        <mesh
          filename="package://vehicle_assembly/meshes/front_left_roller_5.STL" />
      </geometry>
      <material
        name="">
        <color
          rgba="0.792156862745098 0.819607843137255 0.933333333333333 1" />
      </material>
    </visual>
    <collision>
      <origin
        xyz="0 0 0"
        rpy="0 0 0" />
      <geometry>
        <mesh
          filename="package://vehicle_assembly/meshes/front_left_roller_5.STL" />
      </geometry>
    </collision>
  </link>
  <joint
    name="front_left_roller_joint_5"
    type="continuous">
    <origin
      xyz="-0.0250963410938285 -0.000150116835977043 -0.00750296157142988"
      rpy="0.763346740733762 -0.206966081028486 -0.194146383614588" />
    <parent
      link="front_left_wheel" />
    <child
      link="front_left_roller_5" />
    <axis
      xyz="0 0 1" />
  </joint>
  <link
    name="front_left_roller_6">
    <inertial>
      <origin
        xyz="1.11022302462516E-16 5.55111512312578E-17 -0.0139999999999921"
        rpy="0 0 0" />
      <mass
        value="0.00269816712455771" />
      <inertia
        ixx="1.63945498983823E-07"
        ixy="-2.49477672745993E-21"
        ixz="1.37932367143217E-22"
        iyy="1.63945498983829E-07"
        iyz="-7.44462551297725E-24"
        izz="4.74186810998316E-08" />
    </inertial>
    <visual>
      <origin
        xyz="0 0 0"
        rpy="0 0 0" />
      <geometry>
        <mesh
          filename="package://vehicle_assembly/meshes/front_left_roller_6.STL" />
      </geometry>
      <material
        name="">
        <color
          rgba="0.792156862745098 0.819607843137255 0.933333333333333 1" />
      </material>
    </visual>
    <collision>
      <origin
        xyz="0 0 0"
        rpy="0 0 0" />
      <geometry>
        <mesh
          filename="package://vehicle_assembly/meshes/front_left_roller_6.STL" />
      </geometry>
    </collision>
  </link>
  <joint
    name="front_left_roller_joint_6"
    type="continuous">
    <origin
      xyz="-0.0178519416031055 0.0176396443377344 -0.00750296157142982"
      rpy="0.456823171945394 -0.66340612765124 -0.293901499682206" />
    <parent
      link="front_left_wheel" />
    <child
      link="front_left_roller_6" />
    <axis
      xyz="0 0 1" />
  </joint>
  <link
    name="front_left_roller_7">
    <inertial>
      <origin
        xyz="0 0 -0.0139999999999921"
        rpy="0 0 0" />
      <mass
        value="0.00269816712455764" />
      <inertia
        ixx="1.63945498983348E-07"
        ixy="1.65436122510606E-23"
        ixz="2.72969602142499E-23"
        iyy="1.63945498983348E-07"
        iyz="-5.04580173657347E-23"
        izz="4.74186810990826E-08" />
    </inertial>
    <visual>
      <origin
        xyz="0 0 0"
        rpy="0 0 0" />
      <geometry>
        <mesh
          filename="package://vehicle_assembly/meshes/front_left_roller_7.STL" />
      </geometry>
      <material
        name="">
        <color
          rgba="0.792156862745098 0.819607843137255 0.933333333333333 1" />
      </material>
    </visual>
    <collision>
      <origin
        xyz="0 0 0"
        rpy="0 0 0" />
      <geometry>
        <mesh
          filename="package://vehicle_assembly/meshes/front_left_roller_7.STL" />
      </geometry>
    </collision>
  </link>
  <joint
    name="front_left_roller_joint_7"
    type="continuous">
    <origin
      xyz="-0.000150116835970326 0.0250963410938415 -0.00750296157142988"
      rpy="-0.478857784316726 -0.648947247051254 0.304026209991007" />
    <parent
      link="front_left_wheel" />
    <child
      link="front_left_roller_7" />
    <axis
      xyz="0 0 1" />
  </joint>
  <link
    name="front_left_roller_8">
    <inertial>
      <origin
        xyz="4.44089209850063E-16 5.55111512312578E-17 -0.0139999999999922"
        rpy="0 0 0" />
      <mass
        value="0.00269816712455764" />
      <inertia
        ixx="1.63945498982572E-07"
        ixy="3.30872245021211E-24"
        ixz="-2.11758236813575E-22"
        iyy="1.63945498982572E-07"
        iyz="-1.48892510259545E-23"
        izz="4.74186810973265E-08" />
    </inertial>
    <visual>
      <origin
        xyz="0 0 0"
        rpy="0 0 0" />
      <geometry>
        <mesh
          filename="package://vehicle_assembly/meshes/front_left_roller_8.STL" />
      </geometry>
      <material
        name="">
        <color
          rgba="0.792156862745098 0.819607843137255 0.933333333333333 1" />
      </material>
    </visual>
    <collision>
      <origin
        xyz="0 0 0"
        rpy="0 0 0" />
      <geometry>
        <mesh
          filename="package://vehicle_assembly/meshes/front_left_roller_8.STL" />
      </geometry>
    </collision>
  </link>
  <joint
    name="front_left_roller_joint_8"
    type="continuous">
    <origin
      xyz="0.0176396443377416 0.0178519416031188 -0.00750296157142988"
      rpy="-0.766248578899476 -0.193236177895794 0.182756128842418" />
    <parent
      link="front_left_wheel" />
    <child
      link="front_left_roller_8" />
    <axis
      xyz="0 0 1" />
  </joint>
  <link
    name="u3_base_link">
    <inertial>
      <origin
        xyz="-3.66373598126302E-15 4.34895175427386E-15 0.0242014583182471"
        rpy="0 0 0" />
      <mass
        value="0.349927574489805" />
      <inertia
        ixx="0.000850315175929105"
        ixy="6.09825487847888E-20"
        ixz="-2.44269716317236E-20"
        iyy="0.000850315175929105"
        iyz="7.61780752942721E-21"
        izz="0.000961065577007259" />
    </inertial>
    <visual>
      <origin
        xyz="0 0 0"
        rpy="0 0 0" />
      <geometry>
        <mesh
          filename="package://vehicle_assembly/meshes/u3_base_link.STL" />
      </geometry>
      <material
        name="">
        <color
          rgba="0.898039215686275 0.917647058823529 0.929411764705882 1" />
      </material>
    </visual>
    <collision>
      <origin
        xyz="0 0 0"
        rpy="0 0 0" />
      <geometry>
        <mesh
          filename="package://vehicle_assembly/meshes/u3_base_link.STL" />
      </geometry>
    </collision>
  </link>
  <joint
    name="ur_base_joint"
    type="fixed">
    <origin
      xyz="0.162792407799439 0 0.1836"
      rpy="0 0 3.14159265358979" />
    <parent
      link="base_link" />
    <child
      link="u3_base_link" />
    <axis
      xyz="0 0 0" />
  </joint>
  <link
    name="ur3_link_1">
    <inertial>
      <origin
        xyz="-0.000944879708423496 -0.000332184728013527 0.06182506140017"
        rpy="0 0 0" />
      <mass
        value="0.767758063282301" />
      <inertia
        ixx="0.00190285623181829"
        ixy="1.13609715450905E-05"
        ixz="-1.31674712304361E-06"
        iyy="0.00187454926929139"
        iyz="-4.63141040159168E-07"
        izz="0.00150396101327187" />
    </inertial>
    <visual>
      <origin
        xyz="0 0 0"
        rpy="0 0 0" />
      <geometry>
        <mesh
          filename="package://vehicle_assembly/meshes/ur3_link_1.STL" />
      </geometry>
      <material
        name="">
        <color
          rgba="0.647058823529412 0.619607843137255 0.588235294117647 1" />
      </material>
    </visual>
    <collision>
      <origin
        xyz="0 0 0"
        rpy="0 0 0" />
      <geometry>
        <mesh
          filename="package://vehicle_assembly/meshes/ur3_link_1.STL" />
      </geometry>
    </collision>
  </link>
  <joint
    name="ur3_joint_1"
    type="revolute">
    <origin
      xyz="0 0 0.0952"
      rpy="0 0 0" />
    <parent
      link="u3_base_link" />
    <child
      link="ur3_link_1" />
    <axis
      xyz="0 0 1" />
    <limit
      lower="-3.14"
      upper="3.14"
      effort="100"
      velocity="0" />
  </joint>
  <link
    name="ur3_link_2">
    <inertial>
      <origin
        xyz="0.00100159330076943 1.34292318876295E-06 0.0648250634095221"
        rpy="0 0 0" />
      <mass
        value="0.767759568503477" />
      <inertia
        ixx="0.00190685857406092"
        ixy="5.75096352796181E-08"
        ixz="1.39421732619422E-06"
        iyy="0.00187057835883259"
        iyz="2.73861192133087E-09"
        izz="0.00150396554186208" />
    </inertial>
    <visual>
      <origin
        xyz="0 0 0"
        rpy="0 0 0" />
      <geometry>
        <mesh
          filename="package://vehicle_assembly/meshes/ur3_link_2.STL" />
      </geometry>
      <material
        name="">
        <color
          rgba="0.647058823529412 0.619607843137255 0.588235294117647 1" />
      </material>
    </visual>
    <collision>
      <origin
        xyz="0 0 0"
        rpy="0 0 0" />
      <geometry>
        <mesh
          filename="package://vehicle_assembly/meshes/ur3_link_2.STL" />
      </geometry>
    </collision>
  </link>
  <joint
    name="ur3_joint_2"
    type="revolute">
    <origin
      xyz="-0.04717 -0.016582 0.06"
      rpy="0.33805 -1.5708 0" />
    <parent
      link="ur3_link_1" />
    <child
      link="ur3_link_2" />
    <axis
      xyz="0 0 1" />
    <limit
      lower="-3.14"
      upper="3.14"
      effort="100"
      velocity="0" />
  </joint>
  <link
    name="ur3_link_3">
    <inertial>
      <origin
        xyz="-2.96867680622537E-05 8.44469926180418E-05 0.0628250729501241"
        rpy="0 0 0" />
      <mass
        value="0.224135525561565" />
      <inertia
        ixx="0.000556303166609516"
        ixy="1.91465210863904E-10"
        ixz="1.42442205069034E-07"
        iyy="0.000556302689275796"
        iyz="-4.05191155021475E-07"
        izz="0.000254857758078425" />
    </inertial>
    <visual>
      <origin
        xyz="0 0 0"
        rpy="0 0 0" />
      <geometry>
        <mesh
          filename="package://vehicle_assembly/meshes/ur3_link_3.STL" />
      </geometry>
      <material
        name="">
        <color
          rgba="0.898039215686275 0.917647058823529 0.929411764705882 1" />
      </material>
    </visual>
    <collision>
      <origin
        xyz="0 0 0"
        rpy="0 0 0" />
      <geometry>
        <mesh
          filename="package://vehicle_assembly/meshes/ur3_link_3.STL" />
      </geometry>
    </collision>
  </link>
  <joint
    name="ur3_joint_3"
    type="fixed">
    <origin
      xyz="0.05 7.124E-05 0.063"
      rpy="-1.5708 1.2327 -1.5708" />
    <parent
      link="ur3_link_2" />
    <child
      link="ur3_link_3" />
    <axis
      xyz="0 0 0" />
  </joint>
  <link
    name="ur3_link_4">
    <inertial>
      <origin
        xyz="-0.00874125929383562 -0.000374178557858408 0.04123643100441"
        rpy="0 0 0" />
      <mass
        value="0.553968973485341" />
      <inertia
        ixx="0.000760067484811771"
        ixy="-1.0506371260224E-05"
        ixz="8.44783647592584E-06"
        iyy="0.000973043200379829"
        iyz="4.15602899092072E-07"
        izz="0.00097333211634733" />
    </inertial>
    <visual>
      <origin
        xyz="0 0 0"
        rpy="0 0 0" />
      <geometry>
        <mesh
          filename="package://vehicle_assembly/meshes/ur3_link_4.STL" />
      </geometry>
      <material
        name="">
        <color
          rgba="0.647058823529412 0.619607843137255 0.588235294117647 1" />
      </material>
    </visual>
    <collision>
      <origin
        xyz="0 0 0"
        rpy="0 0 0" />
      <geometry>
        <mesh
          filename="package://vehicle_assembly/meshes/ur3_link_4.STL" />
      </geometry>
    </collision>
  </link>
  <joint
    name="ur3_joint_4"
    type="fixed">
    <origin
      xyz="-6.1901E-05 0.00017608 0.131"
      rpy="0 0 0" />
    <parent
      link="ur3_link_3" />
    <child
      link="ur3_link_4" />
    <axis
      xyz="0 0 0" />
  </joint>
  <link
    name="ur3_link_5">
    <inertial>
      <origin
        xyz="-0.0102046788191669 -0.000174922839074564 0.0324859218694459"
        rpy="0 0 0" />
      <mass
        value="0.127554070021426" />
      <inertia
        ixx="0.000153399335619954"
        ixy="2.36558103899377E-09"
        ixz="2.29256993924366E-05"
        iyy="0.000153371570490627"
        iyz="3.94076433052358E-07"
        izz="0.000162700622803482" />
    </inertial>
    <visual>
      <origin
        xyz="0 0 0"
        rpy="0 0 0" />
      <geometry>
        <mesh
          filename="package://vehicle_assembly/meshes/ur3_link_5.STL" />
      </geometry>
      <material
        name="">
        <color
          rgba="0.898039215686275 0.917647058823529 0.929411764705882 1" />
      </material>
    </visual>
    <collision>
      <origin
        xyz="0 0 0"
        rpy="0 0 0" />
      <geometry>
        <mesh
          filename="package://vehicle_assembly/meshes/ur3_link_5.STL" />
      </geometry>
    </collision>
  </link>
  <joint
    name="ur3_joint_5"
    type="revolute">
    <origin
      xyz="0.045924 0.0023213 0.043017"
      rpy="-0.049231 1.5704 0" />
    <parent
      link="ur3_link_4" />
    <child
      link="ur3_link_5" />
    <axis
      xyz="0 0 1" />
    <limit
      lower="-3.14"
      upper="3.14"
      effort="100"
      velocity="0" />
  </joint>
  <link
    name="ur3_link_6">
    <inertial>
      <origin
        xyz="2.39094535587903E-05 -0.000934181849302308 0.0544386476912899"
        rpy="0 0 0" />
      <mass
        value="0.159955499009552" />
      <inertia
        ixx="0.000293152251162613"
        ixy="1.26267672923653E-09"
        ixz="-7.35814056570521E-08"
        iyy="0.000293102948613794"
        iyz="2.87494707656083E-06"
        izz="0.000125617203292675" />
    </inertial>
    <visual>
      <origin
        xyz="0 0 0"
        rpy="0 0 0" />
      <geometry>
        <mesh
          filename="package://vehicle_assembly/meshes/ur3_link_6.STL" />
      </geometry>
      <material
        name="">
        <color
          rgba="0.898039215686275 0.917647058823529 0.929411764705882 1" />
      </material>
    </visual>
    <collision>
      <origin
        xyz="0 0 0"
        rpy="0 0 0" />
      <geometry>
        <mesh
          filename="package://vehicle_assembly/meshes/ur3_link_6.STL" />
      </geometry>
    </collision>
  </link>
  <joint
    name="ur3_joint_6"
    type="fixed">
    <origin
      xyz="-0.044995 -0.00077286 0.04"
      rpy="1.5626 -1.5216 -1.5625" />
    <parent
      link="ur3_link_5" />
    <child
      link="ur3_link_6" />
    <axis
      xyz="0 0 0" />
  </joint>
  <link
    name="ur3_link_7">
    <inertial>
      <origin
        xyz="0.00347139224104931 0.00257335997006167 0.0362108559054254"
        rpy="0 0 0" />
      <mass
        value="0.398536509789194" />
      <inertia
        ixx="0.00044858472584666"
        ixy="-4.76901846000244E-05"
        ixz="-2.63688400460965E-06"
        iyy="0.000456174253311962"
        iyz="-2.48098597384872E-06"
        izz="0.00050265730814257" />
    </inertial>
    <visual>
      <origin
        xyz="0 0 0"
        rpy="0 0 0" />
      <geometry>
        <mesh
          filename="package://vehicle_assembly/meshes/ur3_link_7.STL" />
      </geometry>
      <material
        name="">
        <color
          rgba="0.647058823529412 0.619607843137255 0.588235294117647 1" />
      </material>
    </visual>
    <collision>
      <origin
        xyz="0 0 0"
        rpy="0 0 0" />
      <geometry>
        <mesh
          filename="package://vehicle_assembly/meshes/ur3_link_7.STL" />
      </geometry>
    </collision>
  </link>
  <joint
    name="ur3_joint_7"
    type="fixed">
    <origin
      xyz="5.0281E-05 -0.0019646 0.11448"
      rpy="0 0 0" />
    <parent
      link="ur3_link_6" />
    <child
      link="ur3_link_7" />
    <axis
      xyz="0 0 0" />
  </joint>
  <link
    name="ur3_link_8">
    <inertial>
      <origin
        xyz="1.68480162210383E-06 0.00470541958465592 0.0391624560674754"
        rpy="0 0 0" />
      <mass
        value="0.39853628229664" />
      <inertia
        ixx="0.000500200464430663"
        ixy="-6.102190891016E-08"
        ixz="-1.90465808176435E-09"
        iyy="0.000404466154221167"
        iyz="-2.50429271391386E-06"
        izz="0.000502727269393051" />
    </inertial>
    <visual>
      <origin
        xyz="0 0 0"
        rpy="0 0 0" />
      <geometry>
        <mesh
          filename="package://vehicle_assembly/meshes/ur3_link_8.STL" />
      </geometry>
      <material
        name="">
        <color
          rgba="0.647058823529412 0.619607843137255 0.588235294117647 1" />
      </material>
    </visual>
    <collision>
      <origin
        xyz="0 0 0"
        rpy="0 0 0" />
      <geometry>
        <mesh
          filename="package://vehicle_assembly/meshes/ur3_link_8.STL" />
      </geometry>
    </collision>
  </link>
  <joint
    name="ur3_joint_8"
    type="revolute">
    <origin
      xyz="-0.02899 -0.027452 0.037047"
      rpy="-1.5821 -0.012251 2.317" />
    <parent
      link="ur3_link_7" />
    <child
      link="ur3_link_8" />
    <axis
      xyz="0 0 -1" />
    <limit
      lower="-3.14"
      upper="3.14"
      effort="100"
      velocity="0" />
  </joint>
  <link
    name="ur3_link_9">
    <inertial>
      <origin
        xyz="-0.00697105050859625 0.00885244297474412 0.0397055176266696"
        rpy="0 0 0" />
      <mass
        value="0.557684430697762" />
      <inertia
        ixx="0.000766703957093152"
        ixy="0.000193257153337076"
        ixz="7.10446354592993E-06"
        iyy="0.000644969048783199"
        iyz="-9.72806772950938E-06"
        izz="0.000910512996826322" />
    </inertial>
    <visual>
      <origin
        xyz="0 0 0"
        rpy="0 0 0" />
      <geometry>
        <mesh
          filename="package://vehicle_assembly/meshes/ur3_link_9.STL" />
      </geometry>
      <material
        name="">
        <color
          rgba="0.647058823529412 0.619607843137255 0.588235294117647 1" />
      </material>
    </visual>
    <collision>
      <origin
        xyz="0 0 0"
        rpy="0 0 0" />
      <geometry>
        <mesh
          filename="package://vehicle_assembly/meshes/ur3_link_9.STL" />
      </geometry>
    </collision>
  </link>
  <joint
    name="ur3_joint_9"
    type="revolute">
    <origin
      xyz="-2.5623E-05 -0.0395 0.0405"
      rpy="-1.5875 0.82469 3.1416" />
    <parent
      link="ur3_link_8" />
    <child
      link="ur3_link_9" />
    <axis
      xyz="-0.00044032 0.017159 -0.99985" />
    <limit
      lower="-3.14"
      upper="3.14"
      effort="100"
      velocity="0" />
  </joint>
  <link
    name="ee_link">
    <inertial>
      <origin
        xyz="3.44169137633799E-15 1.11022302462516E-15 0.0286081605526319"
        rpy="0 0 0" />
      <mass
        value="0.228315898214592" />
      <inertia
        ixx="0.000119645757103577"
        ixy="-5.94131375620769E-05"
        ixz="-8.470329472543E-20"
        iyy="0.000220836787212062"
        iyz="-5.62085769842033E-20"
        izz="0.000224958898291664" />
    </inertial>
    <visual>
      <origin
        xyz="0 0 0"
        rpy="0 0 0" />
      <geometry>
        <mesh
          filename="package://vehicle_assembly/meshes/ee_link.STL" />
      </geometry>
      <material
        name="">
        <color
          rgba="0.898039215686275 0.917647058823529 0.929411764705882 1" />
      </material>
    </visual>
    <collision>
      <origin
        xyz="0 0 0"
        rpy="0 0 0" />
      <geometry>
        <mesh
          filename="package://vehicle_assembly/meshes/ee_link.STL" />
      </geometry>
    </collision>
  </link>
  <joint
    name="ee_joint"
    type="revolute">
    <origin
      xyz="-0.032501 0.043655 0.041269"
      rpy="-0.93798 -1.547 0" />
    <parent
      link="ur3_link_9" />
    <child
      link="ee_link" />
    <axis
      xyz="0 0 1" />
    <limit
      lower="-6.28"
      upper="6.28"
      effort="100"
      velocity="0" />
  </joint>
  <link
    name="ee_left_finger">
    <inertial>
      <origin
        xyz="-0.0112888424736179 0.0169540799030595 0.0039870231113443"
        rpy="0 0 0" />
      <mass
        value="0.116532917792388" />
      <inertia
        ixx="6.13768127393589E-05"
        ixy="1.47358333600649E-05"
        ixz="5.68523403742739E-06"
        iyy="4.90577175389812E-05"
        iyz="-8.53833440969669E-06"
        izz="8.48753968585245E-05" />
    </inertial>
    <visual>
      <origin
        xyz="0 0 0"
        rpy="0 0 0" />
      <geometry>
        <mesh
          filename="package://vehicle_assembly/meshes/ee_left_finger.STL" />
      </geometry>
      <material
        name="">
        <color
          rgba="0.792156862745098 0.819607843137255 0.933333333333333 1" />
      </material>
    </visual>
    <collision>
      <origin
        xyz="0 0 0"
        rpy="0 0 0" />
      <geometry>
        <mesh
          filename="package://vehicle_assembly/meshes/ee_left_finger.STL" />
      </geometry>
    </collision>
  </link>
  <joint
    name="ee_left_joint"
    type="prismatic">
    <origin
      xyz="-0.055186 -0.027692 0.052"
      rpy="1.5708 0.58744 2.0035" />
    <parent
      link="ee_link" />
    <child
      link="ee_left_finger" />
    <axis
      xyz="0 0 1" />
    <limit
      lower="-0.2"
      upper="-0.1"
      effort="100"
      velocity="0" />
  </joint>
  <link
    name="ee_right_finger">
    <inertial>
      <origin
        xyz="0.0112888424736186 0.0169540799030595 0.00398702311134419"
        rpy="0 0 0" />
      <mass
        value="0.116532917792387" />
      <inertia
        ixx="6.1376812739353E-05"
        ixy="-1.47358333600591E-05"
        ixz="-5.68523403742776E-06"
        iyy="4.90577175389789E-05"
        iyz="-8.53833440969617E-06"
        izz="8.48753968585155E-05" />
    </inertial>
    <visual>
      <origin
        xyz="0 0 0"
        rpy="0 0 0" />
      <geometry>
        <mesh
          filename="package://vehicle_assembly/meshes/ee_right_finger.STL" />
      </geometry>
      <material
        name="">
        <color
          rgba="0.792156862745098 0.819607843137255 0.933333333333333 1" />
      </material>
    </visual>
    <collision>
      <origin
        xyz="0 0 0"
        rpy="0 0 0" />
      <geometry>
        <mesh
          filename="package://vehicle_assembly/meshes/ee_right_finger.STL" />
      </geometry>
    </collision>
  </link>
  <joint
    name="ee_right_joint"
    type="prismatic">
    <origin
      xyz="0.049587 0.022903 0.052"
      rpy="1.5708 -0.58744 -1.1381" />
    <parent
      link="ee_link" />
    <child
      link="ee_right_finger" />
    <axis
      xyz="0 0 -1" />
    <limit
      lower="0.1"
      upper="0.2"
      effort="100"
      velocity="0" />
  </joint>

<!--############ TRANSMISSION ELEMENTS ###############-->

<!--########### FOR WHEELS ################-->
  <transmission name="rear_left_wheel_trans">
    <type>transmission_interface/SimpleTransmission</type>
    <joint name="rear_left_wheel_joint">
      <hardwareInterface>hardware_interface/VelocityJointInterface</hardwareInterface>
    </joint>
    <actuator name="rear_left_wheel_motor">
      <hardwareInterface>hardware_interface/VelocityJointInterface</hardwareInterface>
      <mechanicalReduction>1</mechanicalReduction>
    </actuator>
  </transmission>

  <transmission name="rear_right_wheel_trans">
    <type>transmission_interface/SimpleTransmission</type>
    <joint name="rear_right_wheel_joint">
      <hardwareInterface>hardware_interface/VelocityJointInterface</hardwareInterface>
    </joint>
    <actuator name="rear_right_wheel_motor">
      <hardwareInterface>hardware_interface/VelocityJointInterface</hardwareInterface>
      <mechanicalReduction>1</mechanicalReduction>
    </actuator>
  </transmission>

  <transmission name="front_left_wheel_trans">
    <type>transmission_interface/SimpleTransmission</type>
    <joint name="front_left_wheel_joint">
      <hardwareInterface>hardware_interface/VelocityJointInterface</hardwareInterface>
    </joint>
    <actuator name="front_left_wheel_motor">
      <hardwareInterface>hardware_interface/VelocityJointInterface</hardwareInterface>
      <mechanicalReduction>1</mechanicalReduction>
    </actuator>
  </transmission>

  <transmission name="front_right_wheel_trans">
    <type>transmission_interface/SimpleTransmission</type>
    <joint name="front_right_wheel_joint">
      <hardwareInterface>hardware_interface/VelocityJointInterface</hardwareInterface>
    </joint>
    <actuator name="front_right_wheel_motor">
      <hardwareInterface>hardware_interface/VelocityJointInterface</hardwareInterface>
      <mechanicalReduction>1</mechanicalReduction>
    </actuator>
  </transmission>

<!--################ FOR ARM ################-->
<transmission name="ur3_joint_1_trans">
    <type>transmission_interface/SimpleTransmission</type>
    <joint name="ur3_joint_1">
      <hardwareInterface>hardware_interface/PositionJointInterface</hardwareInterface>
    </joint>
    <actuator name="ur3_joint_1_motor">
      <hardwareInterface>hardware_interface/PositionJointInterface</hardwareInterface>
      <mechanicalReduction>1</mechanicalReduction>
    </actuator>
  </transmission>

  <transmission name="ur3_joint_2_trans">
    <type>transmission_interface/SimpleTransmission</type>
    <joint name="ur3_joint_2">
      <hardwareInterface>hardware_interface/PositionJointInterface</hardwareInterface>
    </joint>
    <actuator name="ur3_joint_2_motor">
      <hardwareInterface>hardware_interface/PositionJointInterface</hardwareInterface>
      <mechanicalReduction>1</mechanicalReduction>
    </actuator>
  </transmission>

  <transmission name="ur3_joint_5_trans">
    <type>transmission_interface/SimpleTransmission</type>
    <joint name="ur3_joint_5">
      <hardwareInterface>hardware_interface/PositionJointInterface</hardwareInterface>
    </joint>
    <actuator name="ur3_joint_5_motor">
      <hardwareInterface>hardware_interface/PositionJointInterface</hardwareInterface>
      <mechanicalReduction>1</mechanicalReduction>
    </actuator>
  </transmission>

  <transmission name="ur3_joint_8_trans">
    <type>transmission_interface/SimpleTransmission</type>
    <joint name="ur3_joint_8">
      <hardwareInterface>hardware_interface/PositionJointInterface</hardwareInterface>
    </joint>
    <actuator name="ur3_joint_8_motor">
      <hardwareInterface>hardware_interface/PositionJointInterface</hardwareInterface>
      <mechanicalReduction>1</mechanicalReduction>
    </actuator>
  </transmission>

  <transmission name="ur3_joint_9_trans">
    <type>transmission_interface/SimpleTransmission</type>
    <joint name="ur3_joint_9">
      <hardwareInterface>hardware_interface/PositionJointInterface</hardwareInterface>
    </joint>
    <actuator name="ur3_joint_9_motor">
      <hardwareInterface>hardware_interface/PositionJointInterface</hardwareInterface>
      <mechanicalReduction>1</mechanicalReduction>
    </actuator>
  </transmission>

  <transmission name="ee_trans">
    <type>transmission_interface/SimpleTransmission</type>
    <joint name="ee_joint">
      <hardwareInterface>hardware_interface/PositionJointInterface</hardwareInterface>
    </joint>
    <actuator name="ee_motor">
      <hardwareInterface>hardware_interface/PositionJointInterface</hardwareInterface>
      <mechanicalReduction>1</mechanicalReduction>
    </actuator>
  </transmission>

  <transmission name="ee_left_trans">
    <type>transmission_interface/SimpleTransmission</type>
    <joint name="ee_left_joint">
      <hardwareInterface>hardware_interface/PositionJointInterface</hardwareInterface>
    </joint>
    <actuator name="ee_left_joint_motor">
      <hardwareInterface>hardware_interface/PositionJointInterface</hardwareInterface>
      <mechanicalReduction>1</mechanicalReduction>
    </actuator>
  </transmission>

  <transmission name="ee_right_trans">
    <type>transmission_interface/SimpleTransmission</type>
    <joint name="ee_right_joint">
      <hardwareInterface>hardware_interface/PositionJointInterface</hardwareInterface>
    </joint>
    <actuator name="ee_right_joint_motor">
      <hardwareInterface>hardware_interface/PositionJointInterface</hardwareInterface>
      <mechanicalReduction>1</mechanicalReduction>
    </actuator>
  </transmission>

    <!--##########  PLUGINS  ###########3-->
  <gazebo>
    <plugin name="gazebo_ros_control"
     filename="libgazebo_ros_control.so">
    <robotNamespace>/vehicle_assembly</robotNamespace>
    </plugin>
  </gazebo>

  <!-- <gazebo>
		<plugin name="gazebo_ros_control" filename="libgazebo_ros_control.so">
			<robotNamespace>/arm_assembly</robotNamespace>
			<robotSimType>gazebo_ros_control/DefaultRobotHWSim</robotSimType>
			<legacyModeNS>true</legacyModeNS>
		</plugin>
	</gazebo> -->

  <gazebo>
			<plugin name="move_controller" filename="libgazebo_ros_planar_move.so">
        <robotNamespace>/vehicle_assembly</robotNamespace>
				<commandTopic>cmd_vel</commandTopic>
				<odometryTopic>odom</odometryTopic>
				<odometryFrame>odom</odometryFrame>
				<odometryRate>10.0</odometryRate>
				<robotBaseFrame>base_link</robotBaseFrame>
			</plugin>
		</gazebo>

  <gazebo reference="ur3_link_1">
    <selfCollide>true</selfCollide>
  </gazebo>
  <gazebo reference="ur3_link_2">
    <selfCollide>true</selfCollide>
  </gazebo>
  <gazebo reference="ur3_link_3">
    <selfCollide>true</selfCollide>
  </gazebo>
  <gazebo reference="ur3_link_4">
    <selfCollide>true</selfCollide>
  </gazebo>
  <gazebo reference="ur3_link_5">
    <selfCollide>true</selfCollide>
  </gazebo>
  <gazebo reference="ur3_link_6">
    <selfCollide>true</selfCollide>
  </gazebo>
  <gazebo reference="ur3_link_7">
    <selfCollide>true</selfCollide>
  </gazebo>
  <gazebo reference="ur3_link_8">
    <selfCollide>true</selfCollide>
  </gazebo>
  <gazebo reference="ur3_link_9">
    <selfCollide>true</selfCollide>
  </gazebo>
  <gazebo reference="ee_link">
    <selfCollide>true</selfCollide>
  </gazebo>
  <gazebo reference="ee_left_finger">
    <selfCollide>true</selfCollide>
  </gazebo>
  <gazebo reference="ee_right_finger">
    <selfCollide>true</selfCollide>
  </gazebo>
</robot>